<?xml version="1.0" ?>
<robot name="sailboat_materials_description" xmlns:xacro="http://www.ros.org/wiki/xacro">

<xacro:include filename="$(find sailboat_materials_description_description)/urdf/materials.xacro" />
<xacro:include filename="$(find sailboat_materials_description_description)/urdf/sailboat_materials_description.trans" />
<xacro:include filename="$(find sailboat_materials_description_description)/urdf/sailboat_materials_description.gazebo" />
<link name="base_link">
  <inertial>
    <origin xyz="0.8344178909757994 1.8479130700872326e-05 0.4324876083237708" rpy="0 0 0"/>
    <mass value="204.13619400467132"/>
    <inertia ixx="6.489202" iyy="43.141612" izz="47.144813" ixy="-0.002075" iyz="-0.000481" ixz="0.793143"/>
  </inertial>
  <visual>
    <origin xyz="0 0 0" rpy="0 0 0"/>
    <geometry>
      <mesh filename="package://sailboat_materials_description_description/meshes/base_link.stl" scale="0.001 0.001 0.001"/>
    </geometry>
    <material name="silver"/>
  </visual>
  <collision>
    <origin xyz="0 0 0" rpy="0 0 0"/>
    <geometry>
      <mesh filename="package://sailboat_materials_description_description/meshes/base_link.stl" scale="0.001 0.001 0.001"/>
    </geometry>
  </collision>
</link>

<link name="mast_link_1">
  <inertial>
    <origin xyz="2.220446049250313e-16 -1.4210854715202004e-16 0.6499999999999995" rpy="0 0 0"/>
    <mass value="2.481072798172541"/>
    <inertia ixx="0.349557" iyy="0.349557" izz="0.000279" ixy="0.0" iyz="-0.0" ixz="0.0"/>
  </inertial>
  <visual>
    <origin xyz="-0.957 -0.0 -0.5" rpy="0 0 0"/>
    <geometry>
      <mesh filename="package://sailboat_materials_description_description/meshes/mast_link_1.stl" scale="0.001 0.001 0.001"/>
    </geometry>
    <material name="silver"/>
  </visual>
  <collision>
    <origin xyz="-0.957 -0.0 -0.5" rpy="0 0 0"/>
    <geometry>
      <mesh filename="package://sailboat_materials_description_description/meshes/mast_link_1.stl" scale="0.001 0.001 0.001"/>
    </geometry>
  </collision>
</link>

<link name="sail_link_1">
  <inertial>
    <origin xyz="-0.06425696919906199 4.753731293681053e-17 -0.5000000000000011" rpy="0 0 0"/>
    <mass value="24.5920972217098"/>
    <inertia ixx="2.056729" iyy="2.235259" izz="0.193305" ixy="0.0" iyz="-0.0" ixz="0.0"/>
  </inertial>
  <visual>
    <origin xyz="-0.957 -0.0 -1.8" rpy="0 0 0"/>
    <geometry>
      <mesh filename="package://sailboat_materials_description_description/meshes/sail_link_1.stl" scale="0.001 0.001 0.001"/>
    </geometry>
    <material name="silver"/>
  </visual>
  <collision>
    <origin xyz="-0.957 -0.0 -1.8" rpy="0 0 0"/>
    <geometry>
      <mesh filename="package://sailboat_materials_description_description/meshes/sail_link_1.stl" scale="0.001 0.001 0.001"/>
    </geometry>
  </collision>
</link>

<link name="rudder_link_1">
  <inertial>
    <origin xyz="-0.0571587336123294 4.414970727608667e-17 0.1500000000000002" rpy="0 0 0"/>
    <mass value="1.3349130842340802"/>
    <inertia ixx="0.010058" iyy="0.012892" izz="0.002925" ixy="0.0" iyz="-0.0" ixz="0.0"/>
  </inertial>
  <visual>
    <origin xyz="-0.25 -0.0 -0.0" rpy="0 0 0"/>
    <geometry>
      <mesh filename="package://sailboat_materials_description_description/meshes/rudder_link_1.stl" scale="0.001 0.001 0.001"/>
    </geometry>
    <material name="silver"/>
  </visual>
  <collision>
    <origin xyz="-0.25 -0.0 -0.0" rpy="0 0 0"/>
    <geometry>
      <mesh filename="package://sailboat_materials_description_description/meshes/rudder_link_1.stl" scale="0.001 0.001 0.001"/>
    </geometry>
  </collision>
</link>

<link name="pole_link_1">
  <inertial>
    <origin xyz="-2.7755575615628914e-17 0.0 -0.25" rpy="0 0 0"/>
    <mass value="0.23856469213197484"/>
    <inertia ixx="0.004973" iyy="0.004973" izz="7e-06" ixy="-0.0" iyz="0.0" ixz="0.0"/>
  </inertial>
  <visual>
    <origin xyz="-0.25 -0.0 -0.5" rpy="0 0 0"/>
    <geometry>
      <mesh filename="package://sailboat_materials_description_description/meshes/pole_link_1.stl" scale="0.001 0.001 0.001"/>
    </geometry>
    <material name="silver"/>
  </visual>
  <collision>
    <origin xyz="-0.25 -0.0 -0.5" rpy="0 0 0"/>
    <geometry>
      <mesh filename="package://sailboat_materials_description_description/meshes/pole_link_1.stl" scale="0.001 0.001 0.001"/>
    </geometry>
  </collision>
</link>

<joint name="base_mast_joint" type="continuous">
  <origin xyz="0.957 0.0 0.5" rpy="0 0 0"/>
  <parent link="base_link"/>
  <child link="mast_link_1"/>
  <axis xyz="0.0 0.0 1.0"/>
</joint>

<joint name="mast_sail_joint" type="fixed">
  <origin xyz="0.0 0.0 1.3" rpy="0 0 0"/>
  <parent link="mast_link_1"/>
  <child link="sail_link_1"/>
</joint>

<joint name="pole_rudder_joint" type="fixed">
  <origin xyz="0.0 0.0 -0.5" rpy="0 0 0"/>
  <parent link="pole_link_1"/>
  <child link="rudder_link_1"/>
</joint>

<joint name="base_rudder_joint" type="continuous">
  <origin xyz="0.25 0.0 0.5" rpy="0 0 0"/>
  <parent link="base_link"/>
  <child link="pole_link_1"/>
  <axis xyz="0.0 0.0 -1.0"/>
</joint>

</robot>
