<?xml version="1.0"?>
<robot name="sailboat">

<!-- LINKS -->
<!-- Based on format described in: https://classic.gazebosim.org/tutorials?tut=ros_urdf  -->
<!-- Inertial and origin values where taken from the Fusion360 model. -->
  <link name="dummy_link">
  </link>

<!-- Hull (Material: CFRP) -->
  <link name="base_link">
    <inertial>
      <origin xyz="0.8343461090897695 1.8476860883908343e-05 0.4324897304587565" rpy="0 0 0"/>
      <mass value="204.1612"/>
      <inertia ixx="6.489236" ixy="-0.002075" ixz="0.793396" iyy="43.15021" iyz="-0.000481" izz="47.153377"/>
    </inertial>
    <visual>
      <geometry>
        <mesh filename="package://sailboat_description/meshes/hull.dae"/>
      </geometry>
      <origin xyz="0 0 0" rpy="0 0 0"/>
    </visual>
    <collision>
      <geometry>
        <mesh filename="package://sailboat_description/meshes/hull.dae"/>
      </geometry>
      <origin xyz="0 0 0" rpy="0 0 0"/>
    </collision>
  </link>

<!-- Mast (Material: Aluminum) -->
  <link name="mast_link">
    <inertial>
      <origin xyz="2.220446049250313e-16 -1.4210854715202004e-16 0.6499999999999995" rpy="0 0 0"/>
      <mass value="2.481072798172541"/>
      <inertia ixx="0.349557" ixy="0.0" ixz="0.0" iyy="0.349557" iyz="0.0" izz="0.000279"/>
    </inertial>
    <visual>
      <geometry>
        <mesh filename="package://sailboat_description/meshes/mast.dae"/>
      </geometry>
      <origin xyz="-0.957 -0.0 -0.5" rpy="0 0 0"/>
    </visual>
    <collision>
      <geometry>
        <mesh filename="package://sailboat_description/meshes/mast.dae"/>
      </geometry>
      <origin xyz="-0.957 -0.0 -0.5" rpy="0 0 0"/>
    </collision>
  </link>

<!-- Sail (Material: CFRP) -->
  <link name="sail_link">
    <inertial>
      <origin xyz="-1.6151059999999993 0.4579510000000002 0.10333333333333306" rpy="0 0 0"/>
      <mass value="1.7099999999999986"/>
      <inertia ixx="0.095128" iyy="0.148438" izz="0.053566" ixy="0.0" iyz="-0.0" ixz="-0.035625"/>
    </inertial>
    <visual>
      <geometry>
        <mesh filename="package://sailboat_description/meshes/fabric.stl"/>
      </geometry>
      <origin xyz="-2.307106 0.457951 -1.03" rpy="0 0 0"/>
    </visual>
    <collision>
      <geometry>
        <mesh filename="package://sailboat_description/meshes/fabric.stl"/>
      </geometry>
      <origin xyz="-2.307106 0.457951 -1.03" rpy="0 0 0"/>
    </collision>
  </link>

<!-- Pole (Material: Aluminum) -->
  <link name="pole_link">
    <inertial>
      <origin xyz="-2.7755575615628914e-17 0.0 -0.25" rpy="0 0 0"/>  
      <mass value="0.23856469213197484"/>
      <inertia ixx="0.004973" ixy="0.0" ixz="0.0" iyy="0.004973" iyz="0.0" izz="7e-06"/>
    </inertial>
    <visual>  
      <geometry>
        <mesh filename="package://sailboat_description/meshes/pole.dae"/>
      </geometry>
      <origin xyz="-0.25 -0.0 -0.5" rpy="0 0 0"/>
    </visual>
    <collision>
      <geometry>
        <mesh filename="package://sailboat_description/meshes/pole.dae"/>
        <origin xyz="-0.25 -0.0 -0.5" rpy="0 0 0"/>
      </geometry>
    </collision>
  </link>

<!-- Rudder (Material:CFRP) -->
  <link name="rudder_link">
    <inertial>
      <origin xyz="-0.0571587336123294 4.414970727608667e-17 0.1500000000000002" rpy="0 0 0"/>  
      <mass value="1.3349130842340802"/>
      <inertia ixx="0.010058" ixy="0.0" ixz="0.0" iyy="0.012892" iyz="0.0" izz="0.002925"/>
    </inertial>
    <visual>
      <geometry>
        <mesh filename="package://sailboat_description/meshes/rudder.dae"/>
      </geometry>
      <origin xyz="-0.25 -0.0 -0.0" rpy="0 0 0"/>
    </visual>
    <collision>
      <geometry>
        <mesh filename="package://sailboat_description/meshes/rudder.dae"/>
      </geometry>
      <origin xyz="-0.25 -0.0 -0.0" rpy="0 0 0"/>
    </collision>
  </link>

<!-- Camera link -->
  <link name="camera_link">
    <collision>
      <origin xyz="0.00999 0.0 0.0182"/>
      <geometry>
        <box size="0.05 0.05 0.05"/>
      </geometry>
    </collision>
    <visual>
      <origin xyz="0.00999 0.0 0.0182" rpy="0.0 0.0 0.0"/>
      <geometry>
        <box size="0.05 0.05 0.05"/>
      </geometry>
      <material name="black"/>
    </visual>
    <inertial>
      <mass value="1e-5" />
      <origin xyz="0.00999 0 0.0182" rpy="0.0 0.0 0.0"/>
      <inertia ixx="1e-6" ixy="0" ixz="0" iyy="1e-6" iyz="0" izz="1e-6" />
    </inertial>
  </link>

<!-- IMU link -->
  <link name="imu_link">
    <collision>
      <origin xyz="0.00800 0.0 0.05"/>
      <geometry>
        <box size="0.05 0.05 0.05"/>
      </geometry>
    </collision>
    <visual>
      <origin xyz="0.00800 0.0 0.05" rpy="0.0 0.0 0.0"/>
      <geometry>
        <box size="0.05 0.05 0.05"/>
      </geometry>
      <material name="black"/>
    </visual>
    <inertial>
      <mass value="1e-5" />
      <origin xyz="0.00800 0.0 0.05" rpy="0.0 0.0 0.0"/>
      <inertia ixx="1e-6" ixy="0" ixz="0" iyy="1e-6" iyz="0" izz="1e-6" />
    </inertial>
  </link>

<!-- LINK MATERIALS -->
  <gazebo reference="base_link">
    <material>Gazebo/Blue</material>
  </gazebo>

  <gazebo reference="mast_link">
    <material>Gazebo/Gray</material>
  </gazebo>

  <gazebo reference="sail_link">
    <material>Gazebo/White</material>
  </gazebo>

  <gazebo reference="pole_link">
    <material>Gazebo/Gray</material>
  </gazebo>

  <gazebo reference="rudder_link">
    <material>Gazebo/White</material>
  </gazebo>

  <gazebo reference="camera_link">
    <material>Gazebo/Black</material>
  </gazebo>

  <gazebo reference="imu_link">
    <material>Gazebo/Black</material>
  </gazebo>

<!-- JOINTS -->
<!-- Based on format described in: http://wiki.ros.org/urdf/XML/joint -->
  <joint name="dummy_joint" type="fixed">
    <parent link="dummy_link"/>
    <child link="base_link"/>
  </joint>

  <joint name="base_mast_joint" type="revolute">
    <parent link="base_link"/>
    <child link="mast_link"/>
    <axis xyz="0.0 0.0 1.0"/>
    <origin xyz="0.957 0.0 0.5" rpy="0 0 0"/>
    <limit effort="1000.0" lower="-3.14" upper="3.14" velocity="0.5"/>
  </joint>

  <joint name="mast_sail_joint" type="fixed">
    <parent link="mast_link"/>
    <child link="sail_link"/>
    <origin xyz="1.350106 -0.457951 0.53" rpy="0 0 0"/>
  </joint>

  <joint name="base_pole_joint" type="revolute">
    <parent link="base_link"/>
    <child link="pole_link"/>
    <axis xyz="0.0 0.0 -1.0"/>
    <origin xyz="0.25 0.0 0.5" rpy="0.0 0.0 0.0"/>
    <limit effort="1000.0" lower="-3.14" upper="3.14" velocity="0.5"/>
  </joint>

  <joint name="pole_rudder_joint" type="fixed">
    <parent link="pole_link"/>
    <child link="rudder_link"/>
    <origin xyz="0.0 0.0 -0.5" rpy="0.0 0.0 0.0"/>
  </joint>

  <joint name="camera_joint" type="fixed">
    <axis xyz="0.0 1.0 0.0"/>
    <origin xyz="0.0 0.0 1.3"/>
    <parent link="mast_link"/>
    <child link="camera_link"/>
  </joint>

  <joint name="imu_joint" type="fixed">
    <axis xyz="1.0 0.0 0.0"/>
    <origin xyz="0.800 0.0 0.5"/>
    <parent link="base_link"/>
    <child link="imu_link"/>
  </joint>

<!-- TRANSMISSION ELEMENTS -->
<!-- Based on format described in: https://wiki.ros.org/urdf/XML/Transmission -->
  <transmission name="sail_trans">
    <type>transmission_interface/SimpleTransmission</type>
    <joint name="base_mast_joint">
      <hardwareInterface>hardware_interface/PositionJointInterface</hardwareInterface>
    </joint>
    <actuator name="mast_motor">
      <mechanicalReduction>1</mechanicalReduction>
    </actuator>
  </transmission>

  <transmission name="rudder_trans">
    <type>transmission_interface/SimpleTransmission</type>
    <joint name="base_pole_joint">
      <hardwareInterface>hardware_interface/PositionJointInterface</hardwareInterface>
    </joint>
    <actuator name="rudder_motor">
      <mechanicalReduction>1</mechanicalReduction>
    </actuator>
  </transmission>

<!-- SENSORS -->
<!-- Camera -->
  <gazebo reference="camera_link">
    <sensor type="camera" name="camera1">
      <update_rate>30.0</update_rate>
      <camera name="head">
        <horizontal_fov>1.3962634</horizontal_fov>
        <image>
          <width>1920</width>
          <height>1080</height>
          <format>R8G8B8</format>
        </image>
        <clip>
          <near>0.02</near>
          <far>300</far>
        </clip>
        <noise>
          <type>gaussian</type>
          <mean>0.0</mean>
          <stddev>0.007</stddev>
        </noise>
      </camera>
      <plugin name="camera_controller" filename="libgazebo_ros_camera.so">
        <alwaysOn>true</alwaysOn>
        <updateRate>0.0</updateRate>
        <cameraName>sailboat/camera</cameraName>
        <imageTopicName>image_raw</imageTopicName>
        <cameraInfoTopicName>camera_info</cameraInfoTopicName>
        <frameName>camera_link</frameName>
        <hackBaseline>0.07</hackBaseline>
        <distortionK1>0.0</distortionK1>
        <distortionK2>0.0</distortionK2>
        <distortionK3>0.0</distortionK3>
        <distortionT1>0.0</distortionT1>
        <distortionT2>0.0</distortionT2>
      </plugin>
    </sensor>
  </gazebo>

<!-- IMU -->
  <gazebo reference="imu_link">
    <gravity>true</gravity>
    <sensor name="imu_sensor" type="imu">
      <always_on>true</always_on>
      <update_rate>100</update_rate>
      <visualize>true</visualize>
      <topic>__default_topic__</topic>
      <plugin filename="libgazebo_ros_imu_sensor.so" name="imu_plugin">
        <topicName>imu</topicName>
        <bodyName>imu_link</bodyName>
        <updateRateHZ>10.0</updateRateHZ>
        <gaussianNoise>0.0</gaussianNoise>
        <xyzOffset>0 0 0</xyzOffset>
        <rpyOffset>0 0 0</rpyOffset>
        <frameName>imu_link</frameName>
        <initialOrientationAsReference>false</initialOrientationAsReference>
      </plugin>
      <pose>0 0 0 0 0 0</pose>
    </sensor>
  </gazebo>

<!-- PLUGINS -->
<!-- Plugin: gazebo_ros_control  -->
<!-- Based on format described in: https://github.com/ros-simulation/gazebo_ros_pkgs  -->
  <gazebo>
    <plugin name="gazebo_ros_control" filename="libgazebo_ros_control.so">
      <robotNamespace>/sailboat</robotNamespace>
    </plugin>
  </gazebo>
<!-- Plugin: usv_gazebo_dynamics_plugin  -->
<!-- Based on format described in: http://wiki.ros.org/usv_gazebo_plugins -->
  <gazebo>
    <plugin filename="libusv_gazebo_dynamics_plugin.so" name="usv_dynamics_wamv_dynamics_plugin">
      <bodyName>base_link</bodyName>
      <waterLevel>-0.2</waterLevel>
      <waterDensity>997.8</waterDensity>
<!-- Added mass (default values) -->
      <xDotU>0.0</xDotU>
      <yDotV>0.0</yDotV>
      <nDotR>0.0</nDotR>
<!-- Linear and quadratic drag (default values) -->
      <xU>51.30</xU>
      <xUU>72.4</xUU>
      <yV>40.0</yV>
      <yVV>0.0</yVV>
      <zW>500.0</zW>
      <kP>50.0</kP>
      <mQ>50.0</mQ>
      <nR>400.0</nR>
      <nRR>0.0</nRR>
<!-- General dimensions (hull radius pending) -->
      <boatArea>3.674</boatArea>
      <hullRadius>0.213</hullRadius>
      <boatWidth>0.63</boatWidth>
      <boatLength>2.001</boatLength>
<!-- Length discretization, AKA, "N" -->
      <length_n>2</length_n>
      <wave_model>ocean_waves</wave_model>
    </plugin>
  </gazebo>
<!--Plugin: usv_gazebo_wind_plugin -->
  <gazebo>
    <plugin filename="libusv_gazebo_wind_plugin.so" name="wind">
<!-- models to be effected by the wind -->
      <wind_obj>
        <name>sailboat</name>
        <link_name>base_link</link_name>
        <coeff_vector>0.5 0.5 0.33</coeff_vector>
      </wind_obj>
<!-- Wind -->
      <wind_direction>270</wind_direction>
<!-- in degrees -->
      <wind_mean_velocity>10</wind_mean_velocity>
      <var_wind_gain_constants>100</var_wind_gain_constants>
      <var_wind_time_constants>5</var_wind_time_constants>
      <random_seed></random_seed>
<!-- set to zero/empty to randomize -->
      <update_rate>-1</update_rate>
    </plugin>
  </gazebo>
</robot>

