<?xml version="1.0"?>
<robot name="stintboat" xmlns:xacro="http://www.ros.org/wiki/xacro">

  <xacro:include filename="$(find stintboat_description)/urdf/stintboat.gazebo" />
  <xacro:include filename="$(find stintboat_description)/urdf/materials.xacro" />

<!-- LINKS -->
<!-- Based on format described in: https://classic.gazebosim.org/tutorials?tut=ros_urdf  -->
<!-- Inertial and origin values where taken from the Fusion360 model. -->
  <link name="dummy_link">
  </link>

<!-- Hull (Material: CFRP) -->
  <link name="base_link">
    <inertial>
      <origin xyz="0.8343461090897695 1.8476860883908343e-05 0.4324897304587565" rpy="0 0 0"/>
      <mass value="204.1612"/>
      <inertia ixx="6.489236" ixy="-0.002075" ixz="0.793396" iyy="43.15021" iyz="-0.000481" izz="47.153377"/>
    </inertial>
    <visual>
      <geometry>
        <mesh filename="package://stintboat_description/meshes/hull.dae"/>
      </geometry>
      <material name="blue"/>
      <origin xyz="0 0 0" rpy="0 0 0"/>
    </visual>
    <collision>
      <geometry>
        <mesh filename="package://stintboat_description/meshes/hull.dae"/>
      </geometry>
      <origin xyz="0 0 0" rpy="0 0 0"/>
    </collision>
  </link>

<!-- Mast (Material: Aluminum) -->
  <link name="mast_link">
    <inertial>
      <origin xyz="2.220446049250313e-16 -1.4210854715202004e-16 0.6499999999999995" rpy="0 0 0"/>
      <mass value="2.481072798172541"/>
      <inertia ixx="0.349557" ixy="0.0" ixz="0.0" iyy="0.349557" iyz="0.0" izz="0.000279"/>
    </inertial>
    <visual>
      <geometry>
        <mesh filename="package://stintboat_description/meshes/mast.dae"/>
      </geometry>
      <material name="grey"/>
      <origin xyz="-0.957 -0.0 -0.5" rpy="0 0 0"/>
    </visual>
    <collision>
      <geometry>
        <mesh filename="package://stintboat_description/meshes/mast.dae"/>
      </geometry>
      <origin xyz="-0.957 -0.0 -0.5" rpy="0 0 0"/>
    </collision>
  </link>

<!-- Sail (Material: CFRP) -->
  <link name="sail_link">
    <inertial>
      <origin xyz="-0.06425696919906199 4.753731293681053e-17 -0.5000000000000011" rpy="0 0 0"/>
      <mass value="0.021"/>
      <inertia ixx="0.02" ixy="0.0" ixz="0.0" iyy="0.02" iyz="0.0" izz="0.0"/>
    </inertial>
    <visual>
      <geometry>
        <mesh filename="package://stintboat_description/meshes/sail.dae"/>
      </geometry>
      <origin xyz="-0.957 -0.0 -1.8" rpy="0 0 0"/>
    </visual>
    <collision>
      <geometry>
        <mesh filename="package://stintboat_description/meshes/sail.dae"/>
      </geometry>
      <material name="white"/>
      <origin xyz="-0.957 -0.0 -1.8" rpy="0 0 0"/>
    </collision>
  </link>

<!-- Pole (Material: Aluminum) -->
  <link name="pole_link">
    <inertial>
      <origin xyz="-2.7755575615628914e-17 0.0 -0.25" rpy="0 0 0"/>  
      <mass value="0.23856469213197484"/>
      <inertia ixx="0.004973" ixy="0.0" ixz="0.0" iyy="0.004973" iyz="0.0" izz="7e-06"/>
    </inertial>
    <visual>  
      <geometry>
        <mesh filename="package://stintboat_description/meshes/pole.dae"/>
      </geometry>
      <material name="grey"/>
      <origin xyz="-0.25 -0.0 -0.5" rpy="0 0 0"/>
    </visual>
    <collision>
      <geometry>
        <mesh filename="package://stintboat_description/meshes/pole.dae"/>
        <origin xyz="-0.25 -0.0 -0.5" rpy="0 0 0"/>
      </geometry>
    </collision>
  </link>

<!-- Rudder (Material:CFRP) -->
  <link name="rudder_link">
    <inertial>
      <origin xyz="-0.0571587336123294 4.414970727608667e-17 0.1500000000000002" rpy="0 0 0"/>  
      <mass value="1.3349130842340802"/>
      <inertia ixx="0.010058" ixy="0.0" ixz="0.0" iyy="0.012892" iyz="0.0" izz="0.002925"/>
    </inertial>
    <visual>
      <geometry>
        <mesh filename="package://stintboat_description/meshes/rudder.dae"/>
      </geometry>
      <material name="white"/>
      <origin xyz="-0.25 -0.0 -0.0" rpy="0 0 0"/>
    </visual>
    <collision>
      <geometry>
        <mesh filename="package://stintboat_description/meshes/rudder.dae"/>
      </geometry>
      <origin xyz="-0.25 -0.0 -0.0" rpy="0 0 0"/>
    </collision>
  </link>

<!-- Camera link -->
  <link name="camera_link">
    <collision>
      <origin xyz="0.00999 0.0 0.0182"/>
      <geometry>
        <box size="0.05 0.05 0.05"/>
      </geometry>
    </collision>
    <visual>
      <origin xyz="0.00999 0.0 0.0182" rpy="0.0 0.0 0.0"/>
      <geometry>
        <box size="0.05 0.05 0.05"/>
      </geometry>
      <material name="black"/>
    </visual>
    <inertial>
      <mass value="1e-5" />
      <origin xyz="0.00999 0 0.0182" rpy="0.0 0.0 0.0"/>
      <inertia ixx="1e-6" ixy="0" ixz="0" iyy="1e-6" iyz="0" izz="1e-6" />
    </inertial>
  </link>

<!-- IMU link -->
  <link name="imu_link">
    <collision>
      <origin xyz="0.00800 0.0 0.05"/>
      <geometry>
        <box size="0.05 0.05 0.05"/>
      </geometry>
    </collision>
    <visual>
      <origin xyz="0.00800 0.0 0.05" rpy="0.0 0.0 0.0"/>
      <geometry>
        <box size="0.05 0.05 0.05"/>
      </geometry>
      <material name="black"/>
    </visual>
    <inertial>
      <mass value="1e-5" />
      <origin xyz="0.00800 0.0 0.05" rpy="0.0 0.0 0.0"/>
      <inertia ixx="1e-6" ixy="0" ixz="0" iyy="1e-6" iyz="0" izz="1e-6" />
    </inertial>
  </link>

<!-- JOINTS -->
<!-- Based on format described in: http://wiki.ros.org/urdf/XML/joint -->
  <joint name="dummy_joint" type="fixed">
    <parent link="dummy_link"/>
    <child link="base_link"/>
  </joint>

  <joint name="base_mast_joint" type="continuous">
    <parent link="base_link"/>
    <child link="mast_link"/>
    <axis xyz="0.0 0.0 1.0"/>
    <origin xyz="0.957 0.0 0.5" rpy="0 0 0"/>
  </joint>

  <joint name="mast_sail_joint" type="fixed">
    <parent link="mast_link"/>
    <child link="sail_link"/>
    <origin xyz="0.0 0.0 1.3" rpy="0 0 0"/>
  </joint>

  <joint name="base_pole_joint" type="continuous">
    <parent link="base_link"/>
    <child link="pole_link"/>
    <axis xyz="0.0 0.0 -1.0"/>
    <origin xyz="0.25 0.0 0.5" rpy="0.0 0.0 0.0"/>
  </joint>

  <joint name="pole_rudder_joint" type="fixed">
    <parent link="pole_link"/>
    <child link="rudder_link"/>
    <origin xyz="0.0 0.0 -0.5" rpy="0.0 0.0 0.0"/>
  </joint>

  <joint name="camera_joint" type="fixed">
    <axis xyz="0.0 1.0 0.0"/>
    <origin xyz="0.0 0.0 1.3"/>
    <parent link="mast_link"/>
    <child link="camera_link"/>
  </joint>

  <joint name="imu_joint" type="fixed">
    <axis xyz="1.0 0.0 0.0"/>
    <origin xyz="0.800 0.0 0.5"/>
    <parent link="base_link"/>
    <child link="imu_link"/>
  </joint>

<!-- TRANSMISSION ELEMENTS -->
<!-- Based on format described in: https://wiki.ros.org/urdf/XML/Transmission -->
  <transmission name="sail_trans">
    <type>transmission_interface/SimpleTransmission</type>
    <joint name="base_mast_joint">
      <hardwareInterface>hardware_interface/EffortJointInterface</hardwareInterface>
    </joint>
    <actuator name="mast_motor">
      <hardwareInterface>hardware_interface/EffortJointInterface</hardwareInterface>    
      <mechanicalReduction>1</mechanicalReduction>
    </actuator>
  </transmission>

  <transmission name="rudder_trans">
    <type>transmission_interface/SimpleTransmission</type>
    <joint name="base_pole_joint">
      <hardwareInterface>hardware_interface/EffortJointInterface</hardwareInterface>
    </joint>
    <actuator name="rudder_motor">
      <hardwareInterface>hardware_interface/EffortJointInterface</hardwareInterface>
      <mechanicalReduction>1</mechanicalReduction>
    </actuator>
  </transmission>

</robot>



