<?xml version="1.0" ?>
<robot name="raft" xmlns:xacro="http://www.ros.org/wiki/xacro">

<xacro:include filename="$(find raft_description)/urdf/materials.xacro" />
<xacro:include filename="$(find raft_description)/urdf/raft.trans" />
<xacro:include filename="$(find raft_description)/urdf/raft.gazebo" />
<link name="base_link">
  <inertial>
    <origin xyz="0.95 0.0 0.45" rpy="0 0 0"/>
    <mass value="86.01599999999999"/>
    <inertia ixx="4.6592" iyy="31.68256" izz="36.1984" ixy="0.0" iyz="0.0" ixz="0.0"/>
  </inertial>
  <visual>
    <origin xyz="0 0 0" rpy="0 0 0"/>
    <geometry>
      <mesh filename="package://raft_description/meshes/base_link.stl" scale="0.001 0.001 0.001"/>
    </geometry>
    <material name="silver"/>
  </visual>
  <collision>
    <origin xyz="0 0 0" rpy="0 0 0"/>
    <geometry>
      <mesh filename="package://raft_description/meshes/base_link.stl" scale="0.001 0.001 0.001"/>
    </geometry>
  </collision>
</link>

<link name="sail_link_1">
  <inertial>
    <origin xyz="-0.06425696919906188 4.4172629142338264e-17 -0.5000000000000011" rpy="0 0 0"/>
    <mass value="8.805002641619174"/>
    <inertia ixx="0.736395" iyy="0.800317" izz="0.069211" ixy="0.0" iyz="-0.0" ixz="0.0"/>
  </inertial>
  <visual>
    <origin xyz="-0.95 -0.0 -1.8" rpy="0 0 0"/>
    <geometry>
      <mesh filename="package://raft_description/meshes/sail_link_1.stl" scale="0.001 0.001 0.001"/>
    </geometry>
    <material name="silver"/>
  </visual>
  <collision>
    <origin xyz="-0.95 -0.0 -1.8" rpy="0 0 0"/>
    <geometry>
      <mesh filename="package://raft_description/meshes/sail_link_1.stl" scale="0.001 0.001 0.001"/>
    </geometry>
  </collision>
</link>

<link name="mast_link_1">
  <inertial>
    <origin xyz="3.3306690738754696e-16 -1.4210854715202004e-16 0.6499999999999995" rpy="0 0 0"/>
    <mass value="0.47048491580160784"/>
    <inertia ixx="0.066286" iyy="0.066286" izz="5.3e-05" ixy="0.0" iyz="-0.0" ixz="0.0"/>
  </inertial>
  <visual>
    <origin xyz="-0.95 -0.0 -0.5" rpy="0 0 0"/>
    <geometry>
      <mesh filename="package://raft_description/meshes/mast_link_1.stl" scale="0.001 0.001 0.001"/>
    </geometry>
    <material name="silver"/>
  </visual>
  <collision>
    <origin xyz="-0.95 -0.0 -0.5" rpy="0 0 0"/>
    <geometry>
      <mesh filename="package://raft_description/meshes/mast_link_1.stl" scale="0.001 0.001 0.001"/>
    </geometry>
  </collision>
</link>

<joint name="joint2" type="continuous">
  <origin xyz="0.0 0.0 1.3" rpy="0 0 0"/>
  <parent link="mast_link_1"/>
  <child link="sail_link_1"/>
  <axis xyz="0.0 0.0 1.0"/>
</joint>

<joint name="joint1" type="fixed">
  <origin xyz="0.95 0.0 0.5" rpy="0 0 0"/>
  <parent link="base_link"/>
  <child link="mast_link_1"/>
</joint>

</robot>
